Workbook

Sheet Part 1
B2: a)
C10: Initial Portfolio Value | D10: =15000000 -> 15000000
C12: Ticker | D12: Close Price on Apr 17, 2020 | E12: Portfolio Weight | F12: Num of Underlying Shares
C13: CM | D13: =_xlfn.XLOOKUP(DATE(2020,4,17),'CM Prices'!$A$2:$A$504,'CM Prices'!$E$2:$E$504) -> 80.9 | E13: =1/6 -> 0.16666667 | F13: =$D$10*E13/D13 -> 30902.349
C14: BNS | D14: =_xlfn.XLOOKUP(DATE(2020,4,17),'BNS Prices'!$A$2:$A$504,'BNS Prices'!$E$2:$E$504) -> 54.45 | E14: =1/6 -> 0.16666667 | F14: =$D$10*E14/D14 -> 45913.682
C15: TD | D15: =_xlfn.XLOOKUP(DATE(2020,4,17),'TD Prices'!$A$2:$A$504,'TD Prices'!$E$2:$E$504) -> 56.92 | E15: =1/6 -> 0.16666667 | F15: =$D$10*E15/D15 -> 43921.293
C16: BMO | D16: =_xlfn.XLOOKUP(DATE(2020,4,17),'BMO Prices'!$A$2:$A$504,'BMO Prices'!$E$2:$E$504) -> 69.99 | E16: =1/6 -> 0.16666667 | F16: =$D$10*E16/D16 -> 35719.388
C17: NA | D17: =_xlfn.XLOOKUP(DATE(2020,4,17),'NA Prices'!$A$2:$A$504,'NA Prices'!$E$2:$E$504) -> 54.36 | E17: =1/6 -> 0.16666667 | F17: =$D$10*E17/D17 -> 45989.698
C18: RY | D18: =_xlfn.XLOOKUP(DATE(2020,4,17),'RY Prices'!$A$2:$A$504,'RY Prices'!$E$2:$E$504) -> 87.47 | E18: =1/6 -> 0.16666667 | F18: =$D$10*E18/D18 -> 28581.228
B39: b) | C39: Date | D39: CM Close | E39: BNS Close | F39: TD Close | G39: BMO Close | H39: NA Close | I39: RY Close | J39: Daily Portfolio Value | K39: CM Dividends | L39: BNS Dividends | M39: TD Dividends | N39: BMO Dividends | O39: NA Dividends | P39: RY Dividends | Q39: Daily Portfolio Dividend | R39: Daily Log Total Return | T39: Sample Variance
C40: ='CM Prices'!A2 -> 43208 | D40: ='CM Prices'!E2 -> 110.82 | E40: ='BNS Prices'!E2 -> 76.8 | F40: ='TD Prices'!E2 -> 69.97 | G40: ='BMO Prices'!E2 -> 94.99 | H40: ='NA Prices'!E2 -> 59.42 | I40: ='RY Prices'!E2 -> 97 | J40: {=SUMPRODUCT(D40:I40,TRANSPOSE($F$13:$F$18))} -> 18922014 | K40: =IFERROR(VLOOKUP('Part 1'!$C40, 'CM Dividends'!$A:$F, 6, FALSE), 0) -> 0 | L40: =IFERROR(VLOOKUP('Part 1'!$C40, 'BNS Dividends'!$A:$F, 6, FALSE), 0) -> 0 | M40: =IFERROR(VLOOKUP('Part 1'!$C40, 'TD Dividends'!$A:$F, 6, FALSE), 0) -> 0 | N40: =IFERROR(VLOOKUP('Part 1'!$C40, 'BMO Dividends'!$A:$F, 6, FALSE), 0) -> 0 | O40: =IFERROR(VLOOKUP('Part 1'!$C40, 'NA Dividends'!$A:$F, 6, FALSE), 0) -> 0 | P40: =IFERROR(VLOOKUP('Part 1'!$C40, 'RY Dividends'!$A:$F, 6, FALSE), 0) -> 0 | Q40: {=SUMPRODUCT(K40:P40,TRANSPOSE($F$13:$F$18))} -> 0 | T40: =_xlfn.VAR.S(R41:R542) -> 0.00029444211
C41: ='CM Prices'!A3 -> 43209 | D41: ='CM Prices'!E3 -> 110.5 | E41: ='BNS Prices'!E3 -> 76.39 | F41: ='TD Prices'!E3 -> 69.5 | G41: ='BMO Prices'!E3 -> 95.01 | H41: ='NA Prices'!E3 -> 59.22 | I41: ='RY Prices'!E3 -> 96.63 | J41: {=SUMPRODUCT(D41:I41,TRANSPOSE($F$13:$F$18))} -> 18853599 | K41: =IFERROR(VLOOKUP('Part 1'!$C41, 'CM Dividends'!$A:$F, 6, FALSE), 0) -> 0 | L41: =IFERROR(VLOOKUP('Part 1'!$C41, 'BNS Dividends'!$A:$F, 6, FALSE), 0) -> 0 | M41: =IFERROR(VLOOKUP('Part 1'!$C41, 'TD Dividends'!$A:$F, 6, FALSE), 0) -> 0 | N41: =IFERROR(VLOOKUP('Part 1'!$C41, 'BMO Dividends'!$A:$F, 6, FALSE), 0) -> 0 | O41: =IFERROR(VLOOKUP('Part 1'!$C41, 'NA Dividends'!$A:$F, 6, FALSE), 0) -> 0 | P41: =IFERROR(VLOOKUP('Part 1'!$C41, 'RY Dividends'!$A:$F, 6, FALSE), 0) -> 0 | Q41: {=SUMPRODUCT(K41:P41,TRANSPOSE($F$13:$F$18))} -> 0 | R41: =LN((J41+Q41)/J40) -> -0.0036221809
C42: ='CM Prices'!A4 -> 43210 | D42: ='CM Prices'!E4 -> 110.35 | E42: ='BNS Prices'!E4 -> 76.86 | F42: ='TD Prices'!E4 -> 70.19 | G42: ='BMO Prices'!E4 -> 95.57 | H42: ='NA Prices'!E4 -> 59.23 | I42: ='RY Prices'!E4 -> 97.28 | J42: {=SUMPRODUCT(D42:I42,TRANSPOSE($F$13:$F$18))} -> 18939889 | K42: =IFERROR(VLOOKUP('Part 1'!$C42, 'CM Dividends'!$A:$F, 6, FALSE), 0) -> 0 | L42: =IFERROR(VLOOKUP('Part 1'!$C42, 'BNS Dividends'!$A:$F, 6, FALSE), 0) -> 0 | M42: =IFERROR(VLOOKUP('Part 1'!$C42, 'TD Dividends'!$A:$F, 6, FALSE), 0) -> 0 | N42: =IFERROR(VLOOKUP('Part 1'!$C42, 'BMO Dividends'!$A:$F, 6, FALSE), 0) -> 0 | O42: =IFERROR(VLOOKUP('Part 1'!$C42, 'NA Dividends'!$A:$F, 6, FALSE), 0) -> 0 | P42: =IFERROR(VLOOKUP('Part 1'!$C42, 'RY Dividends'!$A:$F, 6, FALSE), 0) -> 0 | Q42: {=SUMPRODUCT(K42:P42,TRANSPOSE($F$13:$F$18))} -> 0 | R42: =LN((J42+Q42)/J41) -> 0.0045664202 | T42: Daily Volatility
C43: ='CM Prices'!A5 -> 43213 | D43: ='CM Prices'!E5 -> 110.62 | E43: ='BNS Prices'!E5 -> 77.46 | F43: ='TD Prices'!E5 -> 70.71 | G43: ='BMO Prices'!E5 -> 96.17 | H43: ='NA Prices'!E5 -> 59.69 | I43: ='RY Prices'!E5 -> 97.98 | J43: {=SUMPRODUCT(D43:I43,TRANSPOSE($F$13:$F$18))} -> 19061214 | K43: =IFERROR(VLOOKUP('Part 1'!$C43, 'CM Dividends'!$A:$F, 6, FALSE), 0) -> 0 | L43: =IFERROR(VLOOKUP('Part 1'!$C43, 'BNS Dividends'!$A:$F, 6, FALSE), 0) -> 0 | M43: =IFERROR(VLOOKUP('Part 1'!$C43, 'TD Dividends'!$A:$F, 6, FALSE), 0) -> 0 | N43: =IFERROR(VLOOKUP('Part 1'!$C43, 'BMO Dividends'!$A:$F, 6, FALSE), 0) -> 0 | O43: =IFERROR(VLOOKUP('Part 1'!$C43, 'NA Dividends'!$A:$F, 6, FALSE), 0) -> 0 | P43: =IFERROR(VLOOKUP('Part 1'!$C43, 'RY Dividends'!$A:$F, 6, FALSE), 0) -> 0 | Q43: {=SUMPRODUCT(K43:P43,TRANSPOSE($F$13:$F$18))} -> 0 | R43: =LN((J43+Q43)/J42) -> 0.0063853453 | T43: =_xlfn.STDEV.S(R41:R542) -> 0.017159315
C44: ='CM Prices'!A6 -> 43214 | D44: ='CM Prices'!E6 -> 110.25 | E44: ='BNS Prices'!E6 -> 77.52 | F44: ='TD Prices'!E6 -> 71.03 | G44: ='BMO Prices'!E6 -> 96.68 | H44: ='NA Prices'!E6 -> 59.89 | I44: ='RY Prices'!E6 -> 96.55 | J44: {=SUMPRODUCT(D44:I44,TRANSPOSE($F$13:$F$18))} -> 19053133 | K44: =IFERROR(VLOOKUP('Part 1'!$C44, 'CM Dividends'!$A:$F, 6, FALSE), 0) -> 0 | L44: =IFERROR(VLOOKUP('Part 1'!$C44, 'BNS Dividends'!$A:$F, 6, FALSE), 0) -> 0 | M44: =IFERROR(VLOOKUP('Part 1'!$C44, 'TD Dividends'!$A:$F, 6, FALSE), 0) -> 0 | N44: =IFERROR(VLOOKUP('Part 1'!$C44, 'BMO Dividends'!$A:$F, 6, FALSE), 0) -> 0 | O44: =IFERROR(VLOOKUP('Part 1'!$C44, 'NA Dividends'!$A:$F, 6, FALSE), 0) -> 0 | P44: =IFERROR(VLOOKUP('Part 1'!$C44, 'RY Dividends'!$A:$F, 6, FALSE), 0) -> 0.94 | Q44: {=SUMPRODUCT(K44:P44,TRANSPOSE($F$13:$F$18))} -> 26866.354 | R44: =LN((J44+Q44)/J43) -> 0.00098506533
C45: ='CM Prices'!A7 -> 43215 | D45: ='CM Prices'!E7 -> 110.83 | E45: ='BNS Prices'!E7 -> 77.66 | F45: ='TD Prices'!E7 -> 71.29 | G45: ='BMO Prices'!E7 -> 97.12 | H45: ='NA Prices'!E7 -> 59.99 | I45: ='RY Prices'!E7 -> 96.61 | J45: {=SUMPRODUCT(D45:I45,TRANSPOSE($F$13:$F$18))} -> 19110934 | K45: =IFERROR(VLOOKUP('Part 1'!$C45, 'CM Dividends'!$A:$F, 6, FALSE), 0) -> 0 | L45: =IFERROR(VLOOKUP('Part 1'!$C45, 'BNS Dividends'!$A:$F, 6, FALSE), 0) -> 0 | M45: =IFERROR(VLOOKUP('Part 1'!$C45, 'TD Dividends'!$A:$F, 6, FALSE), 0) -> 0 | N45: =IFERROR(VLOOKUP('Part 1'!$C45, 'BMO Dividends'!$A:$F, 6, FALSE), 0) -> 0 | O45: =IFERROR(VLOOKUP('Part 1'!$C45, 'NA Dividends'!$A:$F, 6, FALSE), 0) -> 0 | P45: =IFERROR(VLOOKUP('Part 1'!$C45, 'RY Dividends'!$A:$F, 6, FALSE), 0) -> 0 | Q45: {=SUMPRODUCT(K45:P45,TRANSPOSE($F$13:$F$18))} -> 0 | R45: =LN((J45+Q45)/J44) -> 0.0030290918 | T45: Annualized Volatility
C46: ='CM Prices'!A8 -> 43216 | D46: ='CM Prices'!E8 -> 111.98 | E46: ='BNS Prices'!E8 -> 78.62 | F46: ='TD Prices'!E8 -> 72.15 | G46: ='BMO Prices'!E8 -> 97.93 | H46: ='NA Prices'!E8 -> 60.84 | I46: ='RY Prices'!E8 -> 97.18 | J46: {=SUMPRODUCT(D46:I46,TRANSPOSE($F$13:$F$18))} -> 19312637 | K46: =IFERROR(VLOOKUP('Part 1'!$C46, 'CM Dividends'!$A:$F, 6, FALSE), 0) -> 0 | L46: =IFERROR(VLOOKUP('Part 1'!$C46, 'BNS Dividends'!$A:$F, 6, FALSE), 0) -> 0 | M46: =IFERROR(VLOOKUP('Part 1'!$C46, 'TD Dividends'!$A:$F, 6, FALSE), 0) -> 0 | N46: =IFERROR(VLOOKUP('Part 1'!$C46, 'BMO Dividends'!$A:$F, 6, FALSE), 0) -> 0 | O46: =IFERROR(VLOOKUP('Part 1'!$C46, 'NA Dividends'!$A:$F, 6, FALSE), 0) -> 0 | P46: =IFERROR(VLOOKUP('Part 1'!$C46, 'RY Dividends'!$A:$F, 6, FALSE), 0) -> 0 | Q46: {=SUMPRODUCT(K46:P46,TRANSPOSE($F$13:$F$18))} -> 0 | R46: =LN((J46+Q46)/J45) -> 0.010498985 | T46: =T43*SQRT(252) -> 0.27239569
C47: ='CM Prices'!A9 -> 43217 | D47: ='CM Prices'!E9 -> 112.12 | E47: ='BNS Prices'!E9 -> 79.21 | F47: ='TD Prices'!E9 -> 72.26 | G47: ='BMO Prices'!E9 -> 98.51 | H47: ='NA Prices'!E9 -> 61.31 | I47: ='RY Prices'!E9 -> 98.15 | J47: {=SUMPRODUCT(D47:I47,TRANSPOSE($F$13:$F$18))} -> 19418940 | K47: =IFERROR(VLOOKUP('Part 1'!$C47, 'CM Dividends'!$A:$F, 6, FALSE), 0) -> 0 | L47: =IFERROR(VLOOKUP('Part 1'!$C47, 'BNS Dividends'!$A:$F, 6, FALSE), 0) -> 0 | M47: =IFERROR(VLOOKUP('Part 1'!$C47, 'TD Dividends'!$A:$F, 6, FALSE), 0) -> 0 | N47: =IFERROR(VLOOKUP('Part 1'!$C47, 'BMO Dividends'!$A:$F, 6, FALSE), 0) -> 0 | O47: =IFERROR(VLOOKUP('Part 1'!$C47, 'NA Dividends'!$A:$F, 6, FALSE), 0) -> 0 | P47: =IFERROR(VLOOKUP('Part 1'!$C47, 'RY Dividends'!$A:$F, 6, FALSE), 0) -> 0 | Q47: {=SUMPRODUCT(K47:P47,TRANSPOSE($F$13:$F$18))} -> 0 | R47: =LN((J47+Q47)/J46) -> 0.0054892269
C48: ='CM Prices'!A10 -> 43220 | D48: ='CM Prices'!E10 -> 111.83 | E48: ='BNS Prices'!E10 -> 78.92 | F48: ='TD Prices'!E10 -> 72.11 | G48: ='BMO Prices'!E10 -> 97.51 | H48: ='NA Prices'!E10 -> 60.98 | I48: ='RY Prices'!E10 -> 97.64 | J48: {=SUMPRODUCT(D48:I48,TRANSPOSE($F$13:$F$18))} -> 19324602 | K48: =IFERROR(VLOOKUP('Part 1'!$C48, 'CM Dividends'!$A:$F, 6, FALSE), 0) -> 0 | L48: =IFERROR(VLOOKUP('Part 1'!$C48, 'BNS Dividends'!$A:$F, 6, FALSE), 0) -> 0 | M48: =IFERROR(VLOOKUP('Part 1'!$C48, 'TD Dividends'!$A:$F, 6, FALSE), 0) -> 0 | N48: =IFERROR(VLOOKUP('Part 1'!$C48, 'BMO Dividends'!$A:$F, 6, FALSE), 0) -> 0.93 | O48: =IFERROR(VLOOKUP('Part 1'!$C48, 'NA Dividends'!$A:$F, 6, FALSE), 0) -> 0 | P48: =IFERROR(VLOOKUP('Part 1'!$C48, 'RY Dividends'!$A:$F, 6, FALSE), 0) -> 0 | Q48: {=SUMPRODUCT(K48:P48,TRANSPOSE($F$13:$F$18))} -> 33219.031 | R48: =LN((J48+Q48)/J47) -> -0.0031523147
C49: ='CM Prices'!A11 -> 43221 | D49: ='CM Prices'!E11 -> 112.16 | E49: ='BNS Prices'!E11 -> 78.86 | F49: ='TD Prices'!E11 -> 72.3 | G49: ='BMO Prices'!E11 -> 97.76 | H49: ='NA Prices'!E11 -> 61.31 | I49: ='RY Prices'!E11 -> 97.67 | J49: {=SUMPRODUCT(D49:I49,TRANSPOSE($F$13:$F$18))} -> 19365354 | K49: =IFERROR(VLOOKUP('Part 1'!$C49, 'CM Dividends'!$A:$F, 6, FALSE), 0) -> 0 | L49: =IFERROR(VLOOKUP('Part 1'!$C49, 'BNS Dividends'!$A:$F, 6, FALSE), 0) -> 0 | M49: =IFERROR(VLOOKUP('Part 1'!$C49, 'TD Dividends'!$A:$F, 6, FALSE), 0) -> 0 | N49: =IFERROR(VLOOKUP('Part 1'!$C49, 'BMO Dividends'!$A:$F, 6, FALSE), 0) -> 0 | O49: =IFERROR(VLOOKUP('Part 1'!$C49, 'NA Dividends'!$A:$F, 6, FALSE), 0) -> 0 | P49: =IFERROR(VLOOKUP('Part 1'!$C49, 'RY Dividends'!$A:$F, 6, FALSE), 0) -> 0 | Q49: {=SUMPRODUCT(K49:P49,TRANSPOSE($F$13:$F$18))} -> 0 | R49: =LN((J49+Q49)/J48) -> 0.002106588
C50: ='CM Prices'!A12 -> 43222 | D50: ='CM Prices'!E12 -> 112 | E50: ='BNS Prices'!E12 -> 79.08 | F50: ='TD Prices'!E12 -> 72.81 | G50: ='BMO Prices'!E12 -> 97.84 | H50: ='NA Prices'!E12 -> 61.42 | I50: ='RY Prices'!E12 -> 97.71 | J50: {=SUMPRODUCT(D50:I50,TRANSPOSE($F$13:$F$18))} -> 19401970 | K50: =IFERROR(VLOOKUP('Part 1'!$C50, 'CM Dividends'!$A:$F, 6, FALSE), 0) -> 0 | L50: =IFERROR(VLOOKUP('Part 1'!$C50, 'BNS Dividends'!$A:$F, 6, FALSE), 0) -> 0 | M50: =IFERROR(VLOOKUP('Part 1'!$C50, 'TD Dividends'!$A:$F, 6, FALSE), 0) -> 0 | N50: =IFERROR(VLOOKUP('Part 1'!$C50, 'BMO Dividends'!$A:$F, 6, FALSE), 0) -> 0 | O50: =IFERROR(VLOOKUP('Part 1'!$C50, 'NA Dividends'!$A:$F, 6, FALSE), 0) -> 0 | P50: =IFERROR(VLOOKUP('Part 1'!$C50, 'RY Dividends'!$A:$F, 6, FALSE), 0) -> 0 | Q50: {=SUMPRODUCT(K50:P50,TRANSPOSE($F$13:$F$18))} -> 0 | R50: =LN((J50+Q50)/J49) -> 0.0018890224
C51: ='CM Prices'!A13 -> 43223 | D51: ='CM Prices'!E13 -> 112.16 | E51: ='BNS Prices'!E13 -> 78.75 | F51: ='TD Prices'!E13 -> 72.64 | G51: ='BMO Prices'!E13 -> 97.47 | H51: ='NA Prices'!E13 -> 61.26 | I51: ='RY Prices'!E13 -> 97.66 | J51: {=SUMPRODUCT(D51:I51,TRANSPOSE($F$13:$F$18))} -> 19362293 | K51: =IFERROR(VLOOKUP('Part 1'!$C51, 'CM Dividends'!$A:$F, 6, FALSE), 0) -> 0 | L51: =IFERROR(VLOOKUP('Part 1'!$C51, 'BNS Dividends'!$A:$F, 6, FALSE), 0) -> 0 | M51: =IFERROR(VLOOKUP('Part 1'!$C51, 'TD Dividends'!$A:$F, 6, FALSE), 0) -> 0 | N51: =IFERROR(VLOOKUP('Part 1'!$C51, 'BMO Dividends'!$A:$F, 6, FALSE), 0) -> 0 | O51: =IFERROR(VLOOKUP('Part 1'!$C51, 'NA Dividends'!$A:$F, 6, FALSE), 0) -> 0 | P51: =IFERROR(VLOOKUP('Part 1'!$C51, 'RY Dividends'!$A:$F, 6, FALSE), 0) -> 0 | Q51: {=SUMPRODUCT(K51:P51,TRANSPOSE($F$13:$F$18))} -> 0 | R51: =LN((J51+Q51)/J50) -> -0.0020471102
C52: ='CM Prices'!A14 -> 43224 | D52: ='CM Prices'!E14 -> 112.5 | E52: ='BNS Prices'!E14 -> 78.94 | F52: ='TD Prices'!E14 -> 72.93 | G52: ='BMO Prices'!E14 -> 98.05 | H52: ='NA Prices'!E14 -> 61.41 | I52: ='RY Prices'!E14 -> 97.83 | J52: {=SUMPRODUCT(D52:I52,TRANSPOSE($F$13:$F$18))} -> 19426735 | K52: =IFERROR(VLOOKUP('Part 1'!$C52, 'CM Dividends'!$A:$F, 6, FALSE), 0) -> 0 | L52: =IFERROR(VLOOKUP('Part 1'!$C52, 'BNS Dividends'!$A:$F, 6, FALSE), 0) -> 0 | M52: =IFERROR(VLOOKUP('Part 1'!$C52, 'TD Dividends'!$A:$F, 6, FALSE), 0) -> 0 | N52: =IFERROR(VLOOKUP('Part 1'!$C52, 'BMO Dividends'!$A:$F, 6, FALSE), 0) -> 0 | O52: =IFERROR(VLOOKUP('Part 1'!$C52, 'NA Dividends'!$A:$F, 6, FALSE), 0) -> 0 | P52: =IFERROR(VLOOKUP('Part 1'!$C52, 'RY Dividends'!$A:$F, 6, FALSE), 0) -> 0 | Q52: {=SUMPRODUCT(K52:P52,TRANSPOSE($F$13:$F$18))} -> 0 | R52: =LN((J52+Q52)/J51) -> 0.0033226994
C53: ='CM Prices'!A15 -> 43227 | D53: ='CM Prices'!E15 -> 113.34 | E53: ='BNS Prices'!E15 -> 79.35 | F53: ='TD Prices'!E15 -> 73.35 | G53: ='BMO Prices'!E15 -> 98.53 | H53: ='NA Prices'!E15 -> 61.79 | I53: ='RY Prices'!E15 -> 98.76 | J53: {=SUMPRODUCT(D53:I53,TRANSPOSE($F$13:$F$18))} -> 19551167 | K53: =IFERROR(VLOOKUP('Part 1'!$C53, 'CM Dividends'!$A:$F, 6, FALSE), 0) -> 0 | L53: =IFERROR(VLOOKUP('Part 1'!$C53, 'BNS Dividends'!$A:$F, 6, FALSE), 0) -> 0 | M53: =IFERROR(VLOOKUP('Part 1'!$C53, 'TD Dividends'!$A:$F, 6, FALSE), 0) -> 0 | N53: =IFERROR(VLOOKUP('Part 1'!$C53, 'BMO Dividends'!$A:$F, 6, FALSE), 0) -> 0 | O53: =IFERROR(VLOOKUP('Part 1'!$C53, 'NA Dividends'!$A:$F, 6, FALSE), 0) -> 0 | P53: =IFERROR(VLOOKUP('Part 1'!$C53, 'RY Dividends'!$A:$F, 6, FALSE), 0) -> 0 | Q53: {=SUMPRODUCT(K53:P53,TRANSPOSE($F$13:$F$18))} -> 0 | R53: =LN((J53+Q53)/J52) -> 0.0063847399
C54: ='CM Prices'!A16 -> 43228 | D54: ='CM Prices'!E16 -> 113.72 | E54: ='BNS Prices'!E16 -> 79.55 | F54: ='TD Prices'!E16 -> 73.53 | G54: ='BMO Prices'!E16 -> 99.42 | H54: ='NA Prices'!E16 -> 61.93 | I54: ='RY Prices'!E16 -> 98.88 | J54: {=SUMPRODUCT(D54:I54,TRANSPOSE($F$13:$F$18))} -> 19621657 | K54: =IFERROR(VLOOKUP('Part 1'!$C54, 'CM Dividends'!$A:$F, 6, FALSE), 0) -> 0 | L54: =IFERROR(VLOOKUP('Part 1'!$C54, 'BNS Dividends'!$A:$F, 6, FALSE), 0) -> 0 | M54: =IFERROR(VLOOKUP('Part 1'!$C54, 'TD Dividends'!$A:$F, 6, FALSE), 0) -> 0 | N54: =IFERROR(VLOOKUP('Part 1'!$C54, 'BMO Dividends'!$A:$F, 6, FALSE), 0) -> 0 | O54: =IFERROR(VLOOKUP('Part 1'!$C54, 'NA Dividends'!$A:$F, 6, FALSE), 0) -> 0 | P54: =IFERROR(VLOOKUP('Part 1'!$C54, 'RY Dividends'!$A:$F, 6, FALSE), 0) -> 0 | Q54: {=SUMPRODUCT(K54:P54,TRANSPOSE($F$13:$F$18))} -> 0 | R54: =LN((J54+Q54)/J53) -> 0.0035989287
C55: ='CM Prices'!A17 -> 43229 | D55: ='CM Prices'!E17 -> 114.07 | E55: ='BNS Prices'!E17 -> 80 | F55: ='TD Prices'!E17 -> 74.24 | G55: ='BMO Prices'!E17 -> 100.14 | H55: ='NA Prices'!E17 -> 62.56 | I55: ='RY Prices'!E17 -> 99.63 | J55: {=SUMPRODUCT(D55:I55,TRANSPOSE($F$13:$F$18))} -> 19760445 | K55: =IFERROR(VLOOKUP('Part 1'!$C55, 'CM Dividends'!$A:$F, 6, FALSE), 0) -> 0 | L55: =IFERROR(VLOOKUP('Part 1'!$C55, 'BNS Dividends'!$A:$F, 6, FALSE), 0) -> 0 | M55: =IFERROR(VLOOKUP('Part 1'!$C55, 'TD Dividends'!$A:$F, 6, FALSE), 0) -> 0 | N55: =IFERROR(VLOOKUP('Part 1'!$C55, 'BMO Dividends'!$A:$F, 6, FALSE), 0) -> 0 | O55: =IFERROR(VLOOKUP('Part 1'!$C55, 'NA Dividends'!$A:$F, 6, FALSE), 0) -> 0 | P55: =IFERROR(VLOOKUP('Part 1'!$C55, 'RY Dividends'!$A:$F, 6, FALSE), 0) -> 0 | Q55: {=SUMPRODUCT(K55:P55,TRANSPOSE($F$13:$F$18))} -> 0 | R55: =LN((J55+Q55)/J54) -> 0.0070483319
C56: ='CM Prices'!A18 -> 43230 | D56: ='CM Prices'!E18 -> 114.73 | E56: ='BNS Prices'!E18 -> 79.95 | F56: ='TD Prices'!E18 -> 74.28 | G56: ='BMO Prices'!E18 -> 100.34 | H56: ='NA Prices'!E18 -> 62.99 | I56: ='RY Prices'!E18 -> 99.96 | J56: {=SUMPRODUCT(D56:I56,TRANSPOSE($F$13:$F$18))} -> 19816653 | K56: =IFERROR(VLOOKUP('Part 1'!$C56, 'CM Dividends'!$A:$F, 6, FALSE), 0) -> 0 | L56: =IFERROR(VLOOKUP('Part 1'!$C56, 'BNS Dividends'!$A:$F, 6, FALSE), 0) -> 0 | M56: =IFERROR(VLOOKUP('Part 1'!$C56, 'TD Dividends'!$A:$F, 6, FALSE), 0) -> 0 | N56: =IFERROR(VLOOKUP('Part 1'!$C56, 'BMO Dividends'!$A:$F, 6, FALSE), 0) -> 0 | O56: =IFERROR(VLOOKUP('Part 1'!$C56, 'NA Dividends'!$A:$F, 6, FALSE), 0) -> 0 | P56: =IFERROR(VLOOKUP('Part 1'!$C56, 'RY Dividends'!$A:$F, 6, FALSE), 0) -> 0 | Q56: {=SUMPRODUCT(K56:P56,TRANSPOSE($F$13:$F$18))} -> 0 | R56: =LN((J56+Q56)/J55) -> 0.002840431
C57: ='CM Prices'!A19 -> 43231 | D57: ='CM Prices'!E19 -> 115.1 | E57: ='BNS Prices'!E19 -> 80.02 | F57: ='TD Prices'!E19 -> 74.67 | G57: ='BMO Prices'!E19 -> 100.77 | H57: ='NA Prices'!E19 -> 63.35 | I57: ='RY Prices'!E19 -> 100.38 | J57: {=SUMPRODUCT(D57:I57,TRANSPOSE($F$13:$F$18))} -> 19892350 | K57: =IFERROR(VLOOKUP('Part 1'!$C57, 'CM Dividends'!$A:$F, 6, FALSE), 0) -> 0 | L57: =IFERROR(VLOOKUP('Part 1'!$C57, 'BNS Dividends'!$A:$F, 6, FALSE), 0) -> 0 | M57: =IFERROR(VLOOKUP('Part 1'!$C57, 'TD Dividends'!$A:$F, 6, FALSE), 0) -> 0 | N57: =IFERROR(VLOOKUP('Part 1'!$C57, 'BMO Dividends'!$A:$F, 6, FALSE), 0) -> 0 | O57: =IFERROR(VLOOKUP('Part 1'!$C57, 'NA Dividends'!$A:$F, 6, FALSE), 0) -> 0 | P57: =IFERROR(VLOOKUP('Part 1'!$C57, 'RY Dividends'!$A:$F, 6, FALSE), 0) -> 0 | Q57: {=SUMPRODUCT(K57:P57,TRANSPOSE($F$13:$F$18))} -> 0 | R57: =LN((J57+Q57)/J56) -> 0.0038125846
C58: ='CM Prices'!A20 -> 43234 | D58: ='CM Prices'!E20 -> 116.2 | E58: ='BNS Prices'!E20 -> 80.48 | F58: ='TD Prices'!E20 -> 75.08 | G58: ='BMO Prices'!E20 -> 101.14 | H58: ='NA Prices'!E20 -> 63.51 | I58: ='RY Prices'!E20 -> 100.99 | J58: {=SUMPRODUCT(D58:I58,TRANSPOSE($F$13:$F$18))} -> 20003480 | K58: =IFERROR(VLOOKUP('Part 1'!$C58, 'CM Dividends'!$A:$F, 6, FALSE), 0) -> 0 | L58: =IFERROR(VLOOKUP('Part 1'!$C58, 'BNS Dividends'!$A:$F, 6, FALSE), 0) -> 0 | M58: =IFERROR(VLOOKUP('Part 1'!$C58, 'TD Dividends'!$A:$F, 6, FALSE), 0) -> 0 | N58: =IFERROR(VLOOKUP('Part 1'!$C58, 'BMO Dividends'!$A:$F, 6, FALSE), 0) -> 0 | O58: =IFERROR(VLOOKUP('Part 1'!$C58, 'NA Dividends'!$A:$F, 6, FALSE), 0) -> 0 | P58: =IFERROR(VLOOKUP('Part 1'!$C58, 'RY Dividends'!$A:$F, 6, FALSE), 0) -> 0 | Q58: {=SUMPRODUCT(K58:P58,TRANSPOSE($F$13:$F$18))} -> 0 | R58: =LN((J58+Q58)/J57) -> 0.0055710068
... C542: ='CM Prices'!A504 -> 43938 | D542: ='CM Prices'!E504 -> 80.9 | E542: ='BNS Prices'!E504 -> 54.45 | F542: ='TD Prices'!E504 -> 56.92 | G542: ='BMO Prices'!E504 -> 69.99 | H542: ='NA Prices'!E504 -> 54.36 | I542: ='RY Prices'!E504 -> 87.47 | J542: {=SUMPRODUCT(D542:I542,TRANSPOSE($F$13:$F$18))} -> 15000000 | K542: =IFERROR(VLOOKUP('Part 1'!$C542, 'CM Dividends'!$A:$F, 6, FALSE), 0) -> 0 | L542: =IFERROR(VLOOKUP('Part 1'!$C542, 'BNS Dividends'!$A:$F, 6, FALSE), 0) -> 0 | M542: =IFERROR(VLOOKUP('Part 1'!$C542, 'TD Dividends'!$A:$F, 6, FALSE), 0) -> 0 | N542: =IFERROR(VLOOKUP('Part 1'!$C542, 'BMO Dividends'!$A:$F, 6, FALSE), 0) -> 0 | O542: =IFERROR(VLOOKUP('Part 1'!$C542, 'NA Dividends'!$A:$F, 6, FALSE), 0) -> 0 | P542: =IFERROR(VLOOKUP('Part 1'!$C542, 'RY Dividends'!$A:$F, 6, FALSE), 0) -> 0 | Q542: {=SUMPRODUCT(K542:P542,TRANSPOSE($F$13:$F$18))} -> 0 | R542: =LN((J542+Q542)/J541) -> 0.046781459

Sheet Simulated Paths
A1: 0 | B1: 1 | C1: 2 | D1: 3 | E1: 4 | F1: 5 | G1: 6 | H1: 7 | I1: 8 | J1: 9 | K1: 10 | L1: 11 | M1: 12 | N1: 13 | O1: 14 | P1: 15 | Q1: 16 | R1: 17 | S1: 18 | T1: 19 | U1: 20 | V1: 21 | W1: 22 | X1: 23 | Y1: 24 | Z1: 25 | AA1: 26 | AB1: 27 | AC1: 28 | AD1: 29 | AE1: 30 | AF1: 31 | AG1: 32 | AH1: 33 | AI1: 34 | AJ1: 35 | AK1: 36 | AL1: 37 | AM1: 38 | AN1: 39 | AO1: 40 | AP1: 41 | AQ1: 42 | AR1: 43 | AS1: 44 | AT1: 45 | AU1: 46 | AV1: 47 | AW1: 48 | AX1: 49 | AY1: 50 | AZ1: 51 | BA1: 52 | BB1: 53 | BC1: 54 | BD1: 55 | BE1: 56 | BF1: 57 | BG1: 58 | BH1: 59 | BI1: 60 | BJ1: 61 | BK1: 62 | BL1: 63 | BM1: 64 | BN1: 65 | BO1: 66 | BP1: 67 | BQ1: 68 | BR1: 69 | BS1: 70 | BT1: 71 | BU1: 72 | BV1: 73 | BW1: 74 | BX1: 75 | BY1: 76 | BZ1: 77 | CA1: 78 | CB1: 79 | CC1: 80 | CD1: 81 | CE1: 82 | CF1: 83 | CG1: 84 | CH1: 85 | CI1: 86 | CJ1: 87 | CK1: 88 | CL1: 89 | CM1: 90 | CN1: 91 | CO1: 92 | CP1: 93 | CQ1: 94 | CR1: 95 | CS1: 96 | CT1: 97 | CU1: 98 | CV1: 99 | CW1: 100 | CX1: 101 | CY1: 102 | CZ1: 103 | DA1: 104 | DB1: 105 | DC1: 106 | DD1: 107 | DE1: 108 | DF1: 109 | DG1: 110 | DH1: 111 | DI1: 112 | DJ1: 113 | DK1: 114 | DL1: 115 | DM1: 116 | DN1: 117 | DO1: 118 | DP1: 119 | DQ1: 120 | DR1: 121 | DS1: 122 | DT1: 123 | DU1: 124 | DV1: 125 | DW1: 126 | DX1: 127 | DY1: 128 | DZ1: 129 | EA1: 130 | EB1: 131 | EC1: 132 | ED1: 133 | EE1: 134 | EF1: 135 | EG1: 136 | EH1: 137 | EI1: 138 | EJ1: 139 | EK1: 140 | EL1: 141 | EM1: 142 | EN1: 143 | EO1: 144 | EP1: 145 | EQ1: 146 | ER1: 147 | ES1: 148 | ET1: 149 | EU1: 150 | EV1: 151 | EW1: 152 | EX1: 153 | EY1: 154 | EZ1: 155 | FA1: 156 | FB1: 157 | FC1: 158 | FD1: 159 | FE1: 160 | FF1: 161 | FG1: 162 | FH1: 163 | FI1: 164 | FJ1: 165 | FK1: 166 | FL1: 167 | FM1: 168 | FN1: 169 | FO1: 170 | FP1: 171 | FQ1: 172 | FR1: 173 | FS1: 174 | FT1: 175 | FU1: 176 | FV1: 177 | FW1: 178 | FX1: 179 | FY1: 180 | FZ1: 181 | GA1: 182 | GB1: 183 | GC1: 184 | GD1: 185 | GE1: 186 | GF1: 187 | GG1: 188 | GH1: 189 | GI1: 190 | GJ1: 191 | GK1: 192 | GL1: 193 | GM1: 194 | GN1: 195 | GO1: 196 | GP1: 197 | GQ1: 198 | GR1: 199 | GS1: 200 | GT1: 201 | GU1: 202 | GV1: 203 | GW1: 204 | GX1: 205 | GY1: 206 | GZ1: 207 | HA1: 208 | HB1: 209 | HC1: 210 | HD1: 211 | HE1: 212 | HF1: 213 | HG1: 214 | HH1: 215 | HI1: 216 | HJ1: 217 | HK1: 218 | HL1: 219 | HM1: 220 | HN1: 221 | HO1: 222 | HP1: 223 | HQ1: 224 | HR1: 225 | HS1: 226 | HT1: 227 | HU1: 228 | HV1: 229 | HW1: 230 | HX1: 231 | HY1: 232 | HZ1: 233 | IA1: 234 | IB1: 235 | IC1: 236 | ID1: 237 | IE1: 238 | IF1: 239 | IG1: 240 | IH1: 241 | II1: 242 | IJ1: 243 | IK1: 244 | IL1: 245 | IM1: 246 | IN1: 247 | IO1: 248 | IP1: 249 | IQ1: 250 | IR1: 251 | IS1: 252
A2: 100 | B2: 99.015451 | C2: 100.85693 | D2: 100.42287 | E2: 101.99527 | F2: 100.24546 | G2: 98.341876 | H2: 97.040609 | I2: 95.314283 | J2: 92.793866 | K2: 95.855586 | L2: 95.05962 | M2: 96.157283 | N2: 96.792432 | O2: 97.397974 | P2: 96.111252 | Q2: 96.32802 | R2: 97.293919 | S2: 97.723083 | T2: 99.392867 | U2: 99.230141 | V2: 100.89292 | W2: 98.93048 | X2: 98.53668 | Y2: 97.914771 | Z2: 95.823475 | AA2: 96.373293 | AB2: 94.356355 | AC2: 93.460206 | AD2: 93.756579 | AE2: 94.622006 | AF2: 97.110424 | AG2: 98.723301 | AH2: 98.992517 | AI2: 98.77064 | AJ2: 101.15926 | AK2: 98.936422 | AL2: 97.405423 | AM2: 98.592638 | AN2: 100.50387 | AO2: 99.940528 | AP2: 102.08741 | AQ2: 105.67332 | AR2: 104.17957 | AS2: 100.41446 | AT2: 99.490663 | AU2: 99.821472 | AV2: 101.11695 | AW2: 98.611001 | AX2: 96.845364 | AY2: 94.123813 | AZ2: 95.111523 | BA2: 90.276039 | BB2: 87.160971 | BC2: 85.154015 | BD2: 84.789007 | BE2: 86.280281 | BF2: 86.51295 | BG2: 88.033978 | BH2: 86.008502 | BI2: 87.833803 | BJ2: 87.059441 | BK2: 89.283937 | BL2: 90.953414 | BM2: 88.191487 | BN2: 89.731373 | BO2: 89.194152 | BP2: 88.954337 | BQ2: 91.380795 | BR2: 88.736499 | BS2: 88.576298 | BT2: 88.166899 | BU2: 87.117726 | BV2: 88.094537 | BW2: 89.787185 | BX2: 86.92525 | BY2: 90.802359 | BZ2: 92.714293 | CA2: 92.634659 | CB2: 94.327191 | CC2: 93.012644 | CD2: 96.161629 | CE2: 95.527434 | CF2: 96.61922 | CG2: 94.383313 | CH2: 91.867541 | CI2: 96.257457 | CJ2: 97.889429 | CK2: 103.543 | CL2: 99.35147 | CM2: 99.106435 | CN2: 97.556528 | CO2: 101.47034 | CP2: 101.5045 | CQ2: 103.32498 | CR2: 104.04039 | CS2: 108.65856 | CT2: 108.03038 | CU2: 108.85571 | CV2: 110.23963 | CW2: 110.61125 | CX2: 109.96581 | CY2: 109.8989 | CZ2: 111.0166 | DA2: 112.21846 | DB2: 111.12025 | DC2: 110.31894 | DD2: 112.11615 | DE2: 108.89109 | DF2: 110.8685 | DG2: 114.80549 | DH2: 118.51833 | DI2: 117.21719 | DJ2: 116.49961 | DK2: 116.02582 | DL2: 117.97375 | DM2: 118.6676 | DN2: 117.96012 | DO2: 118.6009 | DP2: 120.79008 | DQ2: 121.40113 | DR2: 121.1383 | DS2: 120.84449 | DT2: 118.81439 | DU2: 119.04389 | DV2: 122.23209 | DW2: 123.45972 | DX2: 125.88226 | DY2: 124.75845 | DZ2: 123.34072 | EA2: 123.7266 | EB2: 123.19589 | EC2: 119.65086 | ED2: 119.91789 | EE2: 120.33844 | EF2: 121.99733 | EG2: 122.56485 | EH2: 120.95155 | EI2: 120.1396 | EJ2: 119.9211 | EK2: 118.55107 | EL2: 118.61095 | EM2: 118.18301 | EN2: 121.61976 | EO2: 122.33544 | EP2: 124.14383 | EQ2: 128.52723 | ER2: 127.24159 | ES2: 124.74854 | ET2: 123.18604 | EU2: 125.10644 | EV2: 125.30047 | EW2: 125.71722 | EX2: 123.19334 | EY2: 125.49313 | EZ2: 120.94722 | FA2: 120.36364 | FB2: 121.09775 | FC2: 122.19117 | FD2: 125.56554 | FE2: 129.15077 | FF2: 126.39788 | FG2: 129.54397 | FH2: 129.22206 | FI2: 129.35148 | FJ2: 131.05177 | FK2: 130.6484 | FL2: 131.71964 | FM2: 131.66112 | FN2: 128.32817 | FO2: 126.93941 | FP2: 130.71722 | FQ2: 127.42129 | FR2: 125.55546 | FS2: 123.93142 | FT2: 123.43663 | FU2: 126.7177 | FV2: 126.93708 | FW2: 126.01407 | FX2: 128.01492 | FY2: 125.85819 | FZ2: 128.76076 | GA2: 130.14295 | GB2: 131.65986 | GC2: 132.44716 | GD2: 128.88554 | GE2: 131.52363 | GF2: 128.3862 | GG2: 129.00071 | GH2: 126.93861 | GI2: 125.89755 | GJ2: 128.10651 | GK2: 129.40896 | GL2: 129.27662 | GM2: 127.08233 | GN2: 129.02398 | GO2: 127.2811 | GP2: 126.39774 | GQ2: 124.48165 | GR2: 124.20895 | GS2: 124.6572 | GT2: 123.65815 | GU2: 123.83625 | GV2: 122.31186 | GW2: 119.83106 | GX2: 120.5711 | GY2: 121.41055 | GZ2: 125.83374 | HA2: 127.61612 | HB2: 127.50434 | HC2: 123.83693 | HD2: 124.23284 | HE2: 124.18906 | HF2: 125.34705 | HG2: 125.97598 | HH2: 127.65822 | HI2: 126.68553 | HJ2: 126.95666 | HK2: 127.9031 | HL2: 126.10682 | HM2: 127.79368 | HN2: 129.85993 | HO2: 130.00394 | HP2: 130.41846 | HQ2: 130.32976 | HR2: 131.03569 | HS2: 129.40231 | HT2: 129.66079 | HU2: 128.19551 | HV2: 127.33861 | HW2: 127.94074 | HX2: 129.40909 | HY2: 127.0557 | HZ2: 127.89083 | IA2: 125.70913 | IB2: 124.97133 | IC2: 127.35236 | ID2: 128.37603 | IE2: 129.30634 | IF2: 128.86792 | IG2: 131.20053 | IH2: 133.25152 | II2: 134.50644 | IJ2: 134.62327 | IK2: 136.17528 | IL2: 134.96333 | IM2: 136.80993 | IN2: 135.98739 | IO2: 134.89571 | IP2: 134.58181 | IQ2: 134.30709 | IR2: 135.14354 | IS2: 135.74081
A3: 100 | B3: 100.69973 | C3: 101.0376 | D3: 102.3374 | E3: 105.06922 | F3: 106.78185 | G3: 107.32082 | H3: 105.57458 | I3: 106.01018 | J3: 109.0007 | K3: 107.84346 | L3: 107.76226 | M3: 108.04935 | N3: 108.75019 | O3: 105.9318 | P3: 106.43265 | Q3: 104.2718 | R3: 102.48971 | S3: 102.26932 | T3: 102.03015 | U3: 102.73838 | V3: 101.20103 | W3: 102.14642 | X3: 100.86727 | Y3: 100.66628 | Z3: 100.87697 | AA3: 100.82842 | AB3: 98.347255 | AC3: 100.85503 | AD3: 99.18852 | AE3: 99.950996 | AF3: 99.384203 | AG3: 97.907989 | AH3: 100.09143 | AI3: 98.142908 | AJ3: 97.65881 | AK3: 98.499096 | AL3: 97.736467 | AM3: 96.357275 | AN3: 98.52628 | AO3: 98.315759 | AP3: 98.507733 | AQ3: 98.942934 | AR3: 95.358288 | AS3: 92.218312 | AT3: 90.745254 | AU3: 88.605877 | AV3: 88.979414 | AW3: 89.398861 | AX3: 89.373013 | AY3: 90.187 | AZ3: 90.24422 | BA3: 88.370085 | BB3: 89.178391 | BC3: 88.304139 | BD3: 87.446348 | BE3: 88.338944 | BF3: 87.987108 | BG3: 89.022655 | BH3: 88.267891 | BI3: 88.523246 | BJ3: 88.703035 | BK3: 86.406469 | BL3: 85.860961 | BM3: 84.337114 | BN3: 83.1452 | BO3: 83.852659 | BP3: 83.984468 | BQ3: 84.531161 | BR3: 84.868422 | BS3: 86.957046 | BT3: 88.683573 | BU3: 89.316365 | BV3: 90.421247 | BW3: 91.834535 | BX3: 91.575837 | BY3: 90.780084 | BZ3: 90.428884 | CA3: 91.278569 | CB3: 89.702992 | CC3: 94.264095 | CD3: 93.674424 | CE3: 93.750107 | CF3: 95.443431 | CG3: 96.377245 | CH3: 97.193571 | CI3: 97.419347 | CJ3: 96.785231 | CK3: 97.430703 | CL3: 95.907887 | CM3: 94.194088 | CN3: 94.063183 | CO3: 93.414659 | CP3: 92.538385 | CQ3: 93.458972 | CR3: 91.303367 | CS3: 92.635594 | CT3: 92.018792 | CU3: 94.282156 | CV3: 92.439081 | CW3: 91.908953 | CX3: 89.960132 | CY3: 90.700316 | CZ3: 89.710771 | DA3: 91.147389 | DB3: 89.142502 | DC3: 91.841781 | DD3: 92.259526 | DE3: 90.10942 | DF3: 91.251638 | DG3: 93.344199 | DH3: 91.816204 | DI3: 90.687261 | DJ3: 91.337066 | DK3: 90.478707 | DL3: 90.731815 | DM3: 89.92766 | DN3: 88.717074 | DO3: 87.41693 | DP3: 87.278075 | DQ3: 86.001993 | DR3: 85.039164 | DS3: 83.243044 | DT3: 81.617257 | DU3: 82.164778 | DV3: 81.485712 | DW3: 84.632217 | DX3: 88.90958 | DY3: 88.501303 | DZ3: 86.143114 | EA3: 83.501639 | EB3: 84.362108 | EC3: 81.644796 | ED3: 79.458738 | EE3: 79.362776 | EF3: 78.814812 | EG3: 78.879317 | EH3: 78.306923 | EI3: 79.030909 | EJ3: 77.797582 | EK3: 78.433647 | EL3: 76.903591 | EM3: 76.467639 | EN3: 75.161031 | EO3: 74.800194 | EP3: 75.069621 | EQ3: 76.50117 | ER3: 74.930795 | ES3: 75.396463 | ET3: 74.765555 | EU3: 75.688962 | EV3: 73.339538 | EW3: 72.729702 | EX3: 71.876318 | EY3: 73.307702 | EZ3: 71.319513 | FA3: 68.972975 | FB3: 70.467367 | FC3: 72.690175 | FD3: 70.548825 | FE3: 68.34219 | FF3: 69.341282 | FG3: 71.413617 | FH3: 71.247731 | FI3: 69.539948 | FJ3: 72.728492 | FK3: 71.899436 | FL3: 70.841958 | FM3: 69.833602 | FN3: 73.455892 | FO3: 71.353865 | FP3: 69.93453 | FQ3: 72.051965 | FR3: 71.575712 | FS3: 71.584298 | FT3: 71.220426 | FU3: 70.12275 | FV3: 70.757475 | FW3: 70.100848 | FX3: 71.197921 | FY3: 70.944508 | FZ3: 72.49715 | GA3: 72.24084 | GB3: 71.999523 | GC3: 72.710853 | GD3: 69.599202 | GE3: 70.271838 | GF3: 71.741432 | GG3: 71.254253 | GH3: 72.25925 | GI3: 73.176377 | GJ3: 75.402583 | GK3: 74.792657 | GL3: 74.106376 | GM3: 74.697706 | GN3: 74.71587 | GO3: 73.972127 | GP3: 74.861183 | GQ3: 74.873289 | GR3: 75.243954 | GS3: 75.386167 | GT3: 75.910994 | GU3: 77.24063 | GV3: 77.284394 | GW3: 77.384574 | GX3: 77.078657 | GY3: 76.989077 | GZ3: 76.039446 | HA3: 74.718749 | HB3: 74.809927 | HC3: 72.150642 | HD3: 72.355592 | HE3: 72.746994 | HF3: 74.05742 | HG3: 73.217921 | HH3: 75.035785 | HI3: 74.64248 | HJ3: 73.369911 | HK3: 73.611099 | HL3: 73.944183 | HM3: 73.238187 | HN3: 74.766677 | HO3: 74.033175 | HP3: 73.005889 | HQ3: 74.869381 | HR3: 76.445403 | HS3: 75.768668 | HT3: 78.330599 | HU3: 78.698065 | HV3: 78.990564 | HW3: 78.883534 | HX3: 78.518309 | HY3: 77.413896 | HZ3: 77.309442 | IA3: 76.066059 | IB3: 75.12263 | IC3: 74.306072 | ID3: 74.494943 | IE3: 74.353307 | IF3: 75.465558 | IG3: 74.963954 | IH3: 74.356515 | II3: 74.334317 | IJ3: 74.004866 | IK3: 74.503489 | IL3: 74.58851 | IM3: 73.386559 | IN3: 72.928352 | IO3: 72.770238 | IP3: 71.678621 | IQ3: 70.918299 | IR3: 71.404366 | IS3: 69.130044
A4: 100 | B4: 99.191113 | C4: 102.18126 | D4: 102.98059 | E4: 102.12395 | F4: 101.26349 | G4: 104.80279 | H4: 102.75192 | I4: 102.79913 | J4: 101.93146 | K4: 103.14897 | L4: 104.19775 | M4: 108.20304 | N4: 108.74108 | O4: 107.612 | P4: 108.59463 | Q4: 108.7065 | R4: 111.00172 | S4: 110.6412 | T4: 109.13038 | U4: 106.02205 | V4: 105.22 | W4: 103.03497 | X4: 102.03 | Y4: 102.83824 | Z4: 100.81717 | AA4: 97.613863 | AB4: 97.422307 | AC4: 96.735481 | AD4: 99.971143 | AE4: 99.225878 | AF4: 100.24658 | AG4: 98.93765 | AH4: 102.09222 | AI4: 100.58889 | AJ4: 98.92619 | AK4: 99.266705 | AL4: 97.833254 | AM4: 98.957267 | AN4: 98.86488 | AO4: 100.15017 | AP4: 100.34738 | AQ4: 100.83309 | AR4: 97.920614 | AS4: 97.610952 | AT4: 99.267059 | AU4: 98.782814 | AV4: 96.54488 | AW4: 95.729457 | AX4: 95.039234 | AY4: 93.910013 | AZ4: 90.120253 | BA4: 89.730501 | BB4: 87.175468 | BC4: 88.638737 | BD4: 87.728071 | BE4: 88.017624 | BF4: 86.93743 | BG4: 87.316387 | BH4: 89.982525 | BI4: 91.074008 | BJ4: 89.919836 | BK4: 88.984868 | BL4: 90.495216 | BM4: 89.568691 | BN4: 89.676295 | BO4: 86.773926 | BP4: 84.265917 | BQ4: 81.474157 | BR4: 81.565582 | BS4: 81.093473 | BT4: 81.03752 | BU4: 79.002263 | BV4: 77.485521 | BW4: 77.047355 | BX4: 77.508145 | BY4: 77.452563 | BZ4: 80.619823 | CA4: 81.527686 | CB4: 79.830444 | CC4: 81.682021 | CD4: 82.2677 | CE4: 82.541621 | CF4: 80.985013 | CG4: 80.281458 | CH4: 83.525779 | CI4: 82.677039 | CJ4: 81.886633 | CK4: 82.882249 | CL4: 81.540215 | CM4: 79.845436 | CN4: 79.88218 | CO4: 79.383114 | CP4: 82.134857 | CQ4: 81.962518 | CR4: 82.948621 | CS4: 82.904145 | CT4: 85.848902 | CU4: 84.374371 | CV4: 86.359298 | CW4: 84.778181 | CX4: 83.490607 | CY4: 81.433809 | CZ4: 81.130383 | DA4: 81.693839 | DB4: 81.126596 | DC4: 81.152351 | DD4: 82.771581 | DE4: 81.567781 | DF4: 82.519291 | DG4: 82.068166 | DH4: 80.854201 | DI4: 79.674319 | DJ4: 80.939122 | DK4: 77.755869 | DL4: 78.917204 | DM4: 77.51466 | DN4: 77.374596 | DO4: 77.186087 | DP4: 76.670055 | DQ4: 78.148129 | DR4: 74.142865 | DS4: 76.921462 | DT4: 75.934051 | DU4: 77.504761 | DV4: 77.570071 | DW4: 76.756758 | DX4: 78.027114 | DY4: 76.234521 | DZ4: 78.953697 | EA4: 78.925116 | EB4: 80.512799 | EC4: 78.185321 | ED4: 78.77894 | EE4: 77.540682 | EF4: 78.705314 | EG4: 75.934946 | EH4: 73.755566 | EI4: 76.326923 | EJ4: 76.766998 | EK4: 72.253965 | EL4: 72.053177 | EM4: 73.811614 | EN4: 71.515109 | EO4: 71.225169 | EP4: 70.720161 | EQ4: 69.844365 | ER4: 69.022538 | ES4: 68.906926 | ET4: 69.30532 | EU4: 70.78418 | EV4: 69.759142 | EW4: 69.7356 | EX4: 72.810979 | EY4: 74.01503 | EZ4: 73.668457 | FA4: 75.011595 | FB4: 74.499569 | FC4: 77.173511 | FD4: 77.747836 | FE4: 79.427034 | FF4: 78.397713 | FG4: 77.509755 | FH4: 77.391381 | FI4: 77.072844 | FJ4: 77.12229 | FK4: 79.377066 | FL4: 78.448351 | FM4: 78.519403 | FN4: 78.629777 | FO4: 78.576936 | FP4: 78.710981 | FQ4: 75.615179 | FR4: 76.171734 | FS4: 76.713211 | FT4: 73.511723 | FU4: 74.186589 | FV4: 73.554225 | FW4: 73.457609 | FX4: 72.353836 | FY4: 72.502297 | FZ4: 70.200889 | GA4: 72.127741 | GB4: 72.409263 | GC4: 72.054367 | GD4: 69.374945 | GE4: 68.802642 | GF4: 68.537268 | GG4: 69.443571 | GH4: 69.339426 | GI4: 68.816243 | GJ4: 69.607953 | GK4: 68.898171 | GL4: 67.51633 | GM4: 67.922977 | GN4: 66.483084 | GO4: 69.515307 | GP4: 71.279901 | GQ4: 70.965584 | GR4: 72.025591 | GS4: 73.449718 | GT4: 72.591257 | GU4: 73.93922 | GV4: 71.644858 | GW4: 70.904661 | GX4: 69.846224 | GY4: 70.347269 | GZ4: 72.068686 | HA4: 68.801332 | HB4: 68.751392 | HC4: 65.689138 | HD4: 65.53782 | HE4: 64.114417 | HF4: 65.794868 | HG4: 64.107994 | HH4: 66.749412 | HI4: 66.078383 | HJ4: 65.609184 | HK4: 66.591307 | HL4: 67.058051 | HM4: 67.802008 | HN4: 69.93551 | HO4: 72.124691 | HP4: 72.134025 | HQ4: 73.544604 | HR4: 76.816601 | HS4: 73.719888 | HT4: 79.25573 | HU4: 76.973499 | HV4: 77.177362 | HW4: 74.165071 | HX4: 67.857722 | HY4: 68.058945 | HZ4: 67.655213 | IA4: 64.127207 | IB4: 65.29726 | IC4: 67.806503 | ID4: 66.95741 | IE4: 69.112006 | IF4: 69.21949 | IG4: 69.456877 | IH4: 65.739702 | II4: 66.634271 | IJ4: 65.091186 | IK4: 65.177768 | IL4: 62.611388 | IM4: 59.78243 | IN4: 57.901928 | IO4: 56.909642 | IP4: 57.938991 | IQ4: 56.264791 | IR4: 56.998106 | IS4: 59.722879
A5: 100 | B5: 100.55886 | C5: 99.942148 | D5: 102.38521 | E5: 103.08733 | F5: 103.25452 | G5: 103.29244 | H5: 104.45746 | I5: 104.88983 | J5: 104.72238 | K5: 104.88086 | L5: 105.17321 | M5: 103.79226 | N5: 103.62982 | O5: 105.32797 | P5: 106.45748 | Q5: 105.54308 | R5: 105.23266 | S5: 105.57834 | T5: 106.05796 | U5: 105.83375 | V5: 105.71022 | W5: 107.79532 | X5: 108.18874 | Y5: 109.07515 | Z5: 108.91599 | AA5: 108.31301 | AB5: 107.74132 | AC5: 107.81657 | AD5: 108.28892 | AE5: 108.34168 | AF5: 108.49321 | AG5: 109.24874 | AH5: 109.16663 | AI5: 107.76338 | AJ5: 108.49335 | AK5: 109.78673 | AL5: 110.37904 | AM5: 112.16818 | AN5: 113.42925 | AO5: 113.64204 | AP5: 115.09579 | AQ5: 116.27798 | AR5: 116.54298 | AS5: 116.69158 | AT5: 116.35929 | AU5: 117.89102 | AV5: 116.94757 | AW5: 116.64332 | AX5: 117.18557 | AY5: 119.56458 | AZ5: 119.688 | BA5: 119.25672 | BB5: 119.37191 | BC5: 119.66067 | BD5: 119.24848 | BE5: 119.2568 | BF5: 117.85498 | BG5: 119.37112 | BH5: 118.48816 | BI5: 119.98393 | BJ5: 118.23789 | BK5: 117.58057 | BL5: 116.24059 | BM5: 116.79199 | BN5: 115.51974 | BO5: 113.83252 | BP5: 113.1931 | BQ5: 113.5975 | BR5: 115.0863 | BS5: 114.19123 | BT5: 114.41622 | BU5: 114.77814 | BV5: 114.68911 | BW5: 114.62154 | BX5: 111.94845 | BY5: 113.29362 | BZ5: 113.18274 | CA5: 112.87274 | CB5: 113.57547 | CC5: 114.17531 | CD5: 112.25959 | CE5: 112.39393 | CF5: 110.35582 | CG5: 109.21877 | CH5: 108.46375 | CI5: 108.70241 | CJ5: 107.1893 | CK5: 107.7581 | CL5: 108.32699 | CM5: 108.5807 | CN5: 108.22121 | CO5: 106.77014 | CP5: 105.45188 | CQ5: 106.73923 | CR5: 108.22307 | CS5: 106.70548 | CT5: 107.94854 | CU5: 107.67304 | CV5: 107.71259 | CW5: 108.89307 | CX5: 107.96704 | CY5: 108.02851 | CZ5: 108.25859 | DA5: 108.02166 | DB5: 108.38115 | DC5: 108.38043 | DD5: 107.70974 | DE5: 107.36263 | DF5: 108.12661 | DG5: 108.76274 | DH5: 108.6845 | DI5: 108.65487 | DJ5: 108.33119 | DK5: 108.67871 | DL5: 108.63937 | DM5: 108.52013 | DN5: 108.80903 | DO5: 109.29333 | DP5: 109.54744 | DQ5: 110.10779 | DR5: 111.10941 | DS5: 110.95393 | DT5: 109.92506 | DU5: 109.39865 | DV5: 109.30125 | DW5: 110.21582 | DX5: 110.13522 | DY5: 111.15947 | DZ5: 110.42612 | EA5: 111.39569 | EB5: 112.79997 | EC5: 111.86014 | ED5: 110.92518 | EE5: 109.43269 | EF5: 110.57698 | EG5: 111.61505 | EH5: 112.04122 | EI5: 113.83301 | EJ5: 114.31198 | EK5: 114.53169 | EL5: 115.79201 | EM5: 115.65978 | EN5: 116.28866 | EO5: 116.50915 | EP5: 116.32971 | EQ5: 115.43007 | ER5: 115.6412 | ES5: 115.63823 | ET5: 115.87219 | EU5: 116.46072 | EV5: 117.58162 | EW5: 118.10231 | EX5: 117.90268 | EY5: 117.57358 | EZ5: 117.44057 | FA5: 115.92309 | FB5: 114.8632 | FC5: 114.62896 | FD5: 114.76696 | FE5: 113.44732 | FF5: 112.49757 | FG5: 112.91931 | FH5: 113.40631 | FI5: 113.64819 | FJ5: 114.13627 | FK5: 114.96478 | FL5: 114.488 | FM5: 116.19354 | FN5: 115.91063 | FO5: 115.98968 | FP5: 115.91889 | FQ5: 116.50509 | FR5: 117.92525 | FS5: 118.21172 | FT5: 118.91752 | FU5: 119.74483 | FV5: 119.17782 | FW5: 119.53705 | FX5: 118.05819 | FY5: 118.45288 | FZ5: 118.39003 | GA5: 118.32701 | GB5: 118.41961 | GC5: 119.28751 | GD5: 120.59197 | GE5: 119.89049 | GF5: 119.42331 | GG5: 118.20336 | GH5: 119.5534 | GI5: 119.16448 | GJ5: 121.55053 | GK5: 120.1979 | GL5: 120.61171 | GM5: 120.78823 | GN5: 120.81596 | GO5: 119.4053 | GP5: 117.72508 | GQ5: 118.30636 | GR5: 118.69236 | GS5: 117.5482 | GT5: 116.61997 | GU5: 117.52913 | GV5: 118.03237 | GW5: 117.38547 | GX5: 116.9685 | GY5: 117.8331 | GZ5: 116.85479 | HA5: 118.14254 | HB5: 118.08972 | HC5: 116.62779 | HD5: 116.50391 | HE5: 116.71785 | HF5: 117.11373 | HG5: 118.77672 | HH5: 119.33537 | HI5: 118.91 | HJ5: 118.86225 | HK5: 117.01563 | HL5: 116.44168 | HM5: 116.65788 | HN5: 115.54313 | HO5: 119.39761 | HP5: 120.61284 | HQ5: 120.54605 | HR5: 120.92859 | HS5: 121.71493 | HT5: 119.63918 | HU5: 120.63133 | HV5: 119.33862 | HW5: 120.75549 | HX5: 120.5773 | HY5: 122.11568 | HZ5: 122.64113 | IA5: 127.24823 | IB5: 127.43114 | IC5: 127.73058 | ID5: 127.1834 | IE5: 127.2599 | IF5: 126.05891 | IG5: 126.15949 | IH5: 126.56596 | II5: 124.3482 | IJ5: 124.88413 | IK5: 124.97556 | IL5: 126.31087 | IM5: 128.88324 | IN5: 130.35765 | IO5: 133.28579 | IP5: 132.83685 | IQ5: 132.41487 | IR5: 133.8418 | IS5: 133.76933
A6: 100 | B6: 100.72091 | C6: 99.564342 | D6: 100.72571 | E6: 101.79382 | F6: 100.96446 | G6: 101.99034 | H6: 100.18664 | I6: 97.315016 | J6: 94.327443 | K6: 92.174161 | L6: 91.785859 | M6: 90.917789 | N6: 91.816173 | O6: 89.941436 | P6: 91.418865 | Q6: 89.719804 | R6: 88.523629 | S6: 85.308128 | T6: 83.218163 | U6: 82.866933 | V6: 87.033056 | W6: 86.181785 | X6: 84.583038 | Y6: 82.939024 | Z6: 78.242708 | AA6: 80.848025 | AB6: 79.839391 | AC6: 80.222984 | AD6: 80.581039 | AE6: 81.972287 | AF6: 82.540432 | AG6: 81.327078 | AH6: 82.164768 | AI6: 81.477727 | AJ6: 81.517263 | AK6: 81.000728 | AL6: 80.500741 | AM6: 81.491698 | AN6: 79.75832 | AO6: 80.970559 | AP6: 81.392204 | AQ6: 80.788959 | AR6: 81.305974 | AS6: 81.142069 | AT6: 80.465767 | AU6: 78.999734 | AV6: 78.798053 | AW6: 78.96304 | AX6: 78.128814 | AY6: 79.278104 | AZ6: 79.201654 | BA6: 79.313922 | BB6: 79.468629 | BC6: 78.851535 | BD6: 77.67896 | BE6: 77.169819 | BF6: 76.178226 | BG6: 75.903112 | BH6: 75.653467 | BI6: 77.474005 | BJ6: 76.953905 | BK6: 77.9055 | BL6: 78.242506 | BM6: 78.852976 | BN6: 79.095442 | BO6: 79.078845 | BP6: 77.894275 | BQ6: 77.699134 | BR6: 77.704103 | BS6: 77.079228 | BT6: 77.86248 | BU6: 78.240158 | BV6: 78.140126 | BW6: 79.182152 | BX6: 79.704266 | BY6: 80.191091 | BZ6: 80.53077 | CA6: 79.618935 | CB6: 78.853003 | CC6: 78.201363 | CD6: 76.591891 | CE6: 77.222437 | CF6: 78.222242 | CG6: 77.151841 | CH6: 77.415889 | CI6: 75.908562 | CJ6: 73.304596 | CK6: 73.979199 | CL6: 73.790023 | CM6: 73.508362 | CN6: 72.540861 | CO6: 70.166513 | CP6: 70.497662 | CQ6: 72.042484 | CR6: 71.559772 | CS6: 69.698115 | CT6: 69.465288 | CU6: 69.660109 | CV6: 68.574053 | CW6: 71.453399 | CX6: 69.280696 | CY6: 69.45436 | CZ6: 65.994443 | DA6: 66.925566 | DB6: 64.94165 | DC6: 64.005693 | DD6: 63.436097 | DE6: 67.170752 | DF6: 67.141785 | DG6: 69.800189 | DH6: 72.690829 | DI6: 70.131904 | DJ6: 71.622615 | DK6: 74.653705 | DL6: 75.379668 | DM6: 74.115804 | DN6: 72.460733 | DO6: 74.093336 | DP6: 75.721011 | DQ6: 79.22799 | DR6: 80.78833 | DS6: 80.356989 | DT6: 79.99083 | DU6: 78.989873 | DV6: 80.123179 | DW6: 81.678313 | DX6: 83.184733 | DY6: 83.521574 | DZ6: 83.944112 | EA6: 83.325508 | EB6: 84.011677 | EC6: 86.40546 | ED6: 85.250989 | EE6: 84.597764 | EF6: 83.67671 | EG6: 82.274905 | EH6: 80.177351 | EI6: 81.345566 | EJ6: 78.905161 | EK6: 77.733242 | EL6: 76.738952 | EM6: 73.752746 | EN6: 74.977085 | EO6: 74.853238 | EP6: 74.801162 | EQ6: 75.185582 | ER6: 72.503288 | ES6: 74.226185 | ET6: 73.515503 | EU6: 72.800471 | EV6: 71.416219 | EW6: 71.622924 | EX6: 72.449191 | EY6: 72.931274 | EZ6: 75.074578 | FA6: 74.792525 | FB6: 76.400826 | FC6: 74.328686 | FD6: 73.971261 | FE6: 74.877377 | FF6: 77.655398 | FG6: 77.482225 | FH6: 78.870576 | FI6: 79.786014 | FJ6: 80.938059 | FK6: 80.472782 | FL6: 80.206599 | FM6: 81.258544 | FN6: 82.126871 | FO6: 80.962621 | FP6: 82.641278 | FQ6: 82.374869 | FR6: 83.362996 | FS6: 84.008104 | FT6: 82.585058 | FU6: 81.89177 | FV6: 82.427967 | FW6: 81.250876 | FX6: 81.105762 | FY6: 79.431779 | FZ6: 80.541423 | GA6: 80.852423 | GB6: 82.00573 | GC6: 81.89541 | GD6: 78.891832 | GE6: 78.806376 | GF6: 78.800205 | GG6: 79.367255 | GH6: 80.013053 | GI6: 82.195904 | GJ6: 82.735578 | GK6: 81.439617 | GL6: 81.186803 | GM6: 79.558792 | GN6: 79.347275 | GO6: 81.267474 | GP6: 80.313972 | GQ6: 80.32213 | GR6: 80.695782 | GS6: 81.932852 | GT6: 81.219351 | GU6: 81.776743 | GV6: 81.015949 | GW6: 81.717752 | GX6: 81.31198 | GY6: 83.124068 | GZ6: 82.48888 | HA6: 82.667956 | HB6: 82.083131 | HC6: 83.089685 | HD6: 82.766456 | HE6: 82.31057 | HF6: 82.651838 | HG6: 82.314407 | HH6: 83.773253 | HI6: 82.924458 | HJ6: 82.467862 | HK6: 82.842865 | HL6: 82.761237 | HM6: 84.17788 | HN6: 84.597814 | HO6: 84.650197 | HP6: 83.950393 | HQ6: 82.556489 | HR6: 82.688201 | HS6: 82.594643 | HT6: 82.878448 | HU6: 82.214828 | HV6: 83.190407 | HW6: 84.068248 | HX6: 82.096419 | HY6: 80.973155 | HZ6: 81.051767 | IA6: 82.880883 | IB6: 83.754536 | IC6: 84.162067 | ID6: 83.934227 | IE6: 83.592449 | IF6: 82.648368 | IG6: 83.037361 | IH6: 84.126736 | II6: 85.244418 | IJ6: 85.185618 | IK6: 85.716653 | IL6: 87.381359 | IM6: 87.363197 | IN6: 86.168261 | IO6: 87.129634 | IP6: 85.902893 | IQ6: 85.346438 | IR6: 86.329712 | IS6: 86.154068
A7: 100 | B7: 99.891553 | C7: 100.05104 | D7: 100.65975 | E7: 100.26856 | F7: 98.077425 | G7: 100.53165 | H7: 101.4533 | I7: 102.19601 | J7: 102.62584 | K7: 104.3832 | L7: 105.17 | M7: 105.29364 | N7: 103.33282 | O7: 103.73326 | P7: 103.71042 | Q7: 106.97977 | R7: 106.17852 | S7: 105.40632 | T7: 106.40378 | U7: 107.64177 | V7: 106.41325 | W7: 106.14011 | X7: 108.59876 | Y7: 108.58286 | Z7: 109.26944 | AA7: 108.64263 | AB7: 111.08005 | AC7: 110.91611 | AD7: 110.69081 | AE7: 111.69617 | AF7: 111.41109 | AG7: 110.9169 | AH7: 110.57405 | AI7: 110.46883 | AJ7: 111.16655 | AK7: 111.2043 | AL7: 111.09435 | AM7: 111.4363 | AN7: 111.50227 | AO7: 111.69685 | AP7: 111.25419 | AQ7: 111.11804 | AR7: 111.53104 | AS7: 110.15167 | AT7: 111.03803 | AU7: 110.96579 | AV7: 111.17212 | AW7: 110.95304 | AX7: 111.57069 | AY7: 112.30401 | AZ7: 112.95374 | BA7: 112.86422 | BB7: 112.99973 | BC7: 113.06339 | BD7: 113.13738 | BE7: 113.41391 | BF7: 113.91764 | BG7: 113.98547 | BH7: 114.06715 | BI7: 114.13507 | BJ7: 114.17638 | BK7: 114.43472 | BL7: 114.24816 | BM7: 114.06059 | BN7: 114.02642 | BO7: 116.37856 | BP7: 116.60322 | BQ7: 116.47925 | BR7: 116.6793 | BS7: 117.93287 | BT7: 117.78503 | BU7: 118.51271 | BV7: 118.40719 | BW7: 118.7974 | BX7: 118.98786 | BY7: 119.09291 | BZ7: 120.34431 | CA7: 120.0152 | CB7: 120.21022 | CC7: 119.60736 | CD7: 119.81793 | CE7: 119.85195 | CF7: 119.752 | CG7: 119.27664 | CH7: 119.22465 | CI7: 119.88798 | CJ7: 120.23182 | CK7: 120.57242 | CL7: 118.62454 | CM7: 117.34675 | CN7: 118.2258 | CO7: 118.94309 | CP7: 118.19392 | CQ7: 118.11217 | CR7: 117.68992 | CS7: 117.59469 | CT7: 118.96266 | CU7: 118.83639 | CV7: 118.98923 | CW7: 120.74856 | CX7: 119.71965 | CY7: 119.28316 | CZ7: 121.03186 | DA7: 121.26748 | DB7: 122.38332 | DC7: 120.88951 | DD7: 120.60574 | DE7: 121.564 | DF7: 122.65951 | DG7: 121.87372 | DH7: 122.16704 | DI7: 122.40724 | DJ7: 122.33335 | DK7: 122.7371 | DL7: 123.58525 | DM7: 123.62394 | DN7: 124.39712 | DO7: 123.62007 | DP7: 124.0129 | DQ7: 123.53134 | DR7: 122.64275 | DS7: 121.9595 | DT7: 122.16317 | DU7: 121.36878 | DV7: 121.06735 | DW7: 120.46198 | DX7: 119.94941 | DY7: 120.18706 | DZ7: 120.26857 | EA7: 120.44256 | EB7: 121.20912 | EC7: 121.71559 | ED7: 122.57648 | EE7: 122.18004 | EF7: 122.60057 | EG7: 122.49916 | EH7: 122.49149 | EI7: 121.91739 | EJ7: 122.04753 | EK7: 121.94865 | EL7: 122.36603 | EM7: 120.6166 | EN7: 121.35372 | EO7: 121.06707 | EP7: 120.37516 | EQ7: 118.46959 | ER7: 117.5965 | ES7: 115.56715 | ET7: 115.00286 | EU7: 115.83945 | EV7: 115.10575 | EW7: 114.40748 | EX7: 112.81239 | EY7: 113.49016 | EZ7: 113.06384 | FA7: 113.0672 | FB7: 113.97617 | FC7: 115.66803 | FD7: 115.80528 | FE7: 115.64172 | FF7: 115.51163 | FG7: 116.90102 | FH7: 117.56588 | FI7: 116.74718 | FJ7: 118.09561 | FK7: 116.62204 | FL7: 113.5404 | FM7: 113.42481 | FN7: 113.52921 | FO7: 112.58238 | FP7: 110.46871 | FQ7: 112.19601 | FR7: 112.16388 | FS7: 114.17544 | FT7: 112.83745 | FU7: 114.82305 | FV7: 116.17766 | FW7: 112.551 | FX7: 115.09873 | FY7: 115.63617 | FZ7: 113.19345 | GA7: 113.03725 | GB7: 114.44275 | GC7: 114.95095 | GD7: 115.46809 | GE7: 115.10289 | GF7: 117.59045 | GG7: 118.4794 | GH7: 122.25057 | GI7: 119.48665 | GJ7: 117.87695 | GK7: 116.85402 | GL7: 116.53434 | GM7: 119.51572 | GN7: 123.87326 | GO7: 125.72759 | GP7: 127.83798 | GQ7: 126.61843 | GR7: 126.01851 | GS7: 125.56361 | GT7: 125.17754 | GU7: 124.73642 | GV7: 123.25428 | GW7: 126.24008 | GX7: 126.50309 | GY7: 125.6517 | GZ7: 124.31045 | HA7: 123.90226 | HB7: 125.33219 | HC7: 126.47126 | HD7: 126.11493 | HE7: 124.00806 | HF7: 126.1285 | HG7: 124.79563 | HH7: 126.00666 | HI7: 125.09021 | HJ7: 124.51372 | HK7: 125.93215 | HL7: 126.26968 | HM7: 125.9541 | HN7: 124.9409 | HO7: 127.33266 | HP7: 128.93802 | HQ7: 130.66093 | HR7: 131.49077 | HS7: 130.60131 | HT7: 130.61989 | HU7: 128.47931 | HV7: 127.80495 | HW7: 129.08323 | HX7: 130.25024 | HY7: 128.95035 | HZ7: 129.21323 | IA7: 128.98749 | IB7: 130.8468 | IC7: 130.59798 | ID7: 130.69731 | IE7: 131.95784 | IF7: 128.04525 | IG7: 127.7531 | IH7: 127.18037 | II7: 127.55744 | IJ7: 127.22502 | IK7: 127.56289 | IL7: 128.3069 | IM7: 127.37175 | IN7: 126.88284 | IO7: 126.7583 | IP7: 126.89858 | IQ7: 126.2146 | IR7: 123.77768 | IS7: 123.63043
A8: 100 | B8: 102.29208 | C8: 105.69531 | D8: 104.74987 | E8: 103.30973 | F8: 100.53609 | G8: 101.33986 | H8: 99.113271 | I8: 98.287189 | J8: 98.802015 | K8: 101.84826 | L8: 101.52752 | M8: 97.490775 | N8: 99.29561 | O8: 98.13347 | P8: 95.375935 | Q8: 96.551656 | R8: 96.367214 | S8: 100.91522 | T8: 98.468305 | U8: 96.643349 | V8: 98.320781 | W8: 97.64341 | X8: 97.805252 | Y8: 98.713967 | Z8: 100.16208 | AA8: 97.29118 | AB8: 98.350218 | AC8: 99.775258 | AD8: 100.93698 | AE8: 102.64249 | AF8: 102.37609 | AG8: 103.83042 | AH8: 104.35447 | AI8: 101.26807 | AJ8: 98.825044 | AK8: 100.32941 | AL8: 101.9525 | AM8: 99.215586 | AN8: 97.552129 | AO8: 99.145552 | AP8: 102.72706 | AQ8: 104.53849 | AR8: 103.62205 | AS8: 102.9771 | AT8: 103.1896 | AU8: 103.92706 | AV8: 105.25313 | AW8: 108.23032 | AX8: 108.85415 | AY8: 107.29879 | AZ8: 106.7969 | BA8: 104.7088 | BB8: 103.85999 | BC8: 104.64864 | BD8: 106.96678 | BE8: 109.03293 | BF8: 112.73502 | BG8: 109.89186 | BH8: 106.90003 | BI8: 101.47227 | BJ8: 104.05757 | BK8: 104.19674 | BL8: 104.0574 | BM8: 106.45536 | BN8: 109.51571 | BO8: 109.21789 | BP8: 112.18156 | BQ8: 112.42214 | BR8: 110.61231 | BS8: 112.16375 | BT8: 110.13355 | BU8: 111.15553 | BV8: 109.7486 | BW8: 108.74109 | BX8: 107.16004 | BY8: 105.81681 | BZ8: 104.20668 | CA8: 102.63117 | CB8: 103.62542 | CC8: 102.70995 | CD8: 103.53408 | CE8: 104.69056 | CF8: 103.33166 | CG8: 101.90707 | CH8: 103.4586 | CI8: 103.222 | CJ8: 102.53878 | CK8: 105.06937 | CL8: 104.91536 | CM8: 104.87576 | CN8: 105.25034 | CO8: 106.4936 | CP8: 103.69864 | CQ8: 104.9128 | CR8: 104.99025 | CS8: 107.91386 | CT8: 104.20293 | CU8: 106.92845 | CV8: 104.03391 | CW8: 105.71577 | CX8: 106.01625 | CY8: 107.35705 | CZ8: 107.91503 | DA8: 107.08963 | DB8: 111.04979 | DC8: 111.7974 | DD8: 110.95954 | DE8: 110.81041 | DF8: 108.67285 | DG8: 110.17891 | DH8: 109.98271 | DI8: 110.61306 | DJ8: 110.57529 | DK8: 107.46356 | DL8: 104.28564 | DM8: 104.26384 | DN8: 100.30381 | DO8: 100.04736 | DP8: 100.48169 | DQ8: 96.715291 | DR8: 98.838233 | DS8: 100.31133 | DT8: 100.20594 | DU8: 102.24539 | DV8: 102.88855 | DW8: 104.84653 | DX8: 103.13065 | DY8: 103.81969 | DZ8: 102.74863 | EA8: 109.57993 | EB8: 108.88495 | EC8: 106.97073 | ED8: 106.77185 | EE8: 107.16926 | EF8: 107.64186 | EG8: 109.28844 | EH8: 104.96611 | EI8: 103.72135 | EJ8: 99.8218 | EK8: 100.77934 | EL8: 97.105498 | EM8: 96.143477 | EN8: 98.054913 | EO8: 97.527322 | EP8: 96.959511 | EQ8: 97.471345 | ER8: 97.531814 | ES8: 96.640367 | ET8: 97.296057 | EU8: 98.359775 | EV8: 93.793326 | EW8: 94.318252 | EX8: 96.784281 | EY8: 96.054185 | EZ8: 97.564998 | FA8: 95.294928 | FB8: 94.273809 | FC8: 93.853965 | FD8: 95.312839 | FE8: 92.521667 | FF8: 91.479603 | FG8: 92.918503 | FH8: 94.262372 | FI8: 95.335015 | FJ8: 95.786785 | FK8: 99.094819 | FL8: 95.924958 | FM8: 96.604643 | FN8: 96.885419 | FO8: 99.342284 | FP8: 96.982701 | FQ8: 96.644988 | FR8: 98.610958 | FS8: 100.94191 | FT8: 98.620743 | FU8: 99.804714 | FV8: 100.74541 | FW8: 100.79352 | FX8: 103.37911 | FY8: 104.96705 | FZ8: 106.3885 | GA8: 106.36775 | GB8: 106.37392 | GC8: 107.16958 | GD8: 106.75688 | GE8: 104.91984 | GF8: 106.56885 | GG8: 106.72991 | GH8: 106.22726 | GI8: 107.395 | GJ8: 109.15786 | GK8: 110.49755 | GL8: 108.09906 | GM8: 109.11258 | GN8: 109.37419 | GO8: 111.71576 | GP8: 114.63431 | GQ8: 115.19903 | GR8: 115.10236 | GS8: 115.02179 | GT8: 116.34427 | GU8: 115.74641 | GV8: 116.35065 | GW8: 116.15377 | GX8: 116.21556 | GY8: 115.18841 | GZ8: 114.96873 | HA8: 115.47141 | HB8: 114.53392 | HC8: 114.00725 | HD8: 113.56836 | HE8: 113.92511 | HF8: 112.17348 | HG8: 110.96053 | HH8: 111.59197 | HI8: 109.52079 | HJ8: 110.66712 | HK8: 109.06629 | HL8: 110.57362 | HM8: 111.15529 | HN8: 109.83414 | HO8: 108.38528 | HP8: 110.06752 | HQ8: 109.86194 | HR8: 109.66198 | HS8: 109.39298 | HT8: 109.05909 | HU8: 114.16419 | HV8: 111.57905 | HW8: 111.05765 | HX8: 111.35773 | HY8: 110.43709 | HZ8: 110.48965 | IA8: 110.40919 | IB8: 105.67028 | IC8: 104.64359 | ID8: 104.1835 | IE8: 104.45014 | IF8: 103.82629 | IG8: 102.31405 | IH8: 98.288407 | II8: 97.456372 | IJ8: 97.961903 | IK8: 97.574384 | IL8: 99.564661 | IM8: 99.530872 | IN8: 97.415059 | IO8: 95.631738 | IP8: 96.60931 | IQ8: 96.731155 | IR8: 93.95438 | IS8: 93.27143
A9: 100 | B9: 98.53801 | C9: 101.33381 | D9: 100.5961 | E9: 102.213 | F9: 102.32435 | G9: 102.68682 | H9: 102.32488 | I9: 99.166956 | J9: 97.680444 | K9: 97.293005 | L9: 96.956136 | M9: 94.924198 | N9: 94.03742 | O9: 92.61782 | P9: 89.884908 | Q9: 90.809308 | R9: 89.878424 | S9: 87.952307 | T9: 85.636166 | U9: 87.199449 | V9: 85.289592 | W9: 84.189923 | X9: 86.763076 | Y9: 88.744112 | Z9: 85.787027 | AA9: 86.112699 | AB9: 83.302301 | AC9: 84.987323 | AD9: 83.723798 | AE9: 85.333965 | AF9: 82.009541 | AG9: 82.650696 | AH9: 86.39266 | AI9: 90.908173 | AJ9: 87.407776 | AK9: 81.229727 | AL9: 80.929677 | AM9: 78.852743 | AN9: 81.340105 | AO9: 77.924933 | AP9: 83.37123 | AQ9: 86.583912 | AR9: 83.804523 | AS9: 82.67742 | AT9: 80.559016 | AU9: 79.946088 | AV9: 79.866753 | AW9: 81.360365 | AX9: 79.119268 | AY9: 79.110194 | AZ9: 81.609057 | BA9: 77.396451 | BB9: 77.349291 | BC9: 77.174231 | BD9: 84.2533 | BE9: 85.095316 | BF9: 91.775881 | BG9: 94.687386 | BH9: 94.485031 | BI9: 93.710041 | BJ9: 93.735317 | BK9: 92.496851 | BL9: 95.52049 | BM9: 94.639317 | BN9: 91.876934 | BO9: 92.489032 | BP9: 89.568801 | BQ9: 91.053358 | BR9: 91.817462 | BS9: 94.285036 | BT9: 95.410693 | BU9: 94.086281 | BV9: 95.218419 | BW9: 93.519282 | BX9: 93.436941 | BY9: 92.078329 | BZ9: 93.630397 | CA9: 92.127343 | CB9: 92.188063 | CC9: 92.924899 | CD9: 91.787165 | CE9: 96.467039 | CF9: 94.410083 | CG9: 97.30045 | CH9: 95.996494 | CI9: 96.831767 | CJ9: 94.233583 | CK9: 94.937022 | CL9: 92.427306 | CM9: 92.127772 | CN9: 95.964192 | CO9: 101.83511 | CP9: 105.79238 | CQ9: 109.09208 | CR9: 113.31491 | CS9: 115.40948 | CT9: 117.95102 | CU9: 118.84766 | CV9: 117.15186 | CW9: 116.7526 | CX9: 118.722 | CY9: 117.34088 | CZ9: 115.78469 | DA9: 113.58141 | DB9: 121.43312 | DC9: 120.84014 | DD9: 115.55222 | DE9: 113.52473 | DF9: 114.57949 | DG9: 116.93331 | DH9: 121.66065 | DI9: 123.66555 | DJ9: 121.91688 | DK9: 121.55527 | DL9: 116.47258 | DM9: 113.38318 | DN9: 107.88491 | DO9: 106.95849 | DP9: 105.10963 | DQ9: 107.85939 | DR9: 108.42316 | DS9: 106.96216 | DT9: 109.03048 | DU9: 108.51091 | DV9: 111.18222 | DW9: 108.00531 | DX9: 111.38188 | DY9: 112.68472 | DZ9: 115.14302 | EA9: 115.40411 | EB9: 115.87189 | EC9: 113.39633 | ED9: 111.01822 | EE9: 107.51107 | EF9: 108.77655 | EG9: 109.9809 | EH9: 109.52177 | EI9: 111.75767 | EJ9: 111.10527 | EK9: 111.17233 | EL9: 111.57335 | EM9: 112.17592 | EN9: 113.91601 | EO9: 111.15133 | EP9: 111.35802 | EQ9: 116.57806 | ER9: 115.43807 | ES9: 117.0372 | ET9: 117.89857 | EU9: 123.27633 | EV9: 125.48557 | EW9: 129.48977 | EX9: 133.77261 | EY9: 132.39081 | EZ9: 130.15193 | FA9: 127.80923 | FB9: 126.92232 | FC9: 126.98365 | FD9: 126.39974 | FE9: 125.94077 | FF9: 129.35621 | FG9: 127.62126 | FH9: 125.24601 | FI9: 120.40865 | FJ9: 121.38556 | FK9: 119.25282 | FL9: 113.7281 | FM9: 115.49599 | FN9: 117.46762 | FO9: 116.73686 | FP9: 119.17787 | FQ9: 122.97146 | FR9: 126.05782 | FS9: 131.03024 | FT9: 133.38065 | FU9: 132.91288 | FV9: 132.34161 | FW9: 129.57669 | FX9: 130.78129 | FY9: 132.75797 | FZ9: 128.1235 | GA9: 124.17046 | GB9: 130.08808 | GC9: 130.90419 | GD9: 129.89507 | GE9: 130.64707 | GF9: 130.62948 | GG9: 128.51105 | GH9: 132.68072 | GI9: 130.79322 | GJ9: 133.78279 | GK9: 136.49081 | GL9: 143.32656 | GM9: 139.12204 | GN9: 140.60251 | GO9: 141.90073 | GP9: 140.98024 | GQ9: 143.78084 | GR9: 142.85137 | GS9: 145.34859 | GT9: 144.89555 | GU9: 142.66788 | GV9: 142.11733 | GW9: 143.03504 | GX9: 143.86949 | GY9: 143.86254 | GZ9: 143.26524 | HA9: 147.56202 | HB9: 147.63582 | HC9: 148.27661 | HD9: 150.24456 | HE9: 149.23511 | HF9: 151.35265 | HG9: 150.87476 | HH9: 151.1455 | HI9: 150.4881 | HJ9: 148.74195 | HK9: 148.25274 | HL9: 147.00244 | HM9: 147.82405 | HN9: 145.28733 | HO9: 143.16231 | HP9: 142.75549 | HQ9: 147.13295 | HR9: 147.05924 | HS9: 145.45235 | HT9: 145.39259 | HU9: 148.81007 | HV9: 148.73635 | HW9: 147.85851 | HX9: 146.56551 | HY9: 149.44242 | HZ9: 148.91589 | IA9: 148.40055 | IB9: 150.53712 | IC9: 148.5045 | ID9: 149.5992 | IE9: 149.35311 | IF9: 151.1581 | IG9: 151.27971 | IH9: 151.27234 | II9: 151.7245 | IJ9: 150.24316 | IK9: 149.80486 | IL9: 149.9183 | IM9: 148.86213 | IN9: 149.45608 | IO9: 152.59558 | IP9: 152.32191 | IQ9: 153.12015 | IR9: 153.5136 | IS9: 152.5773
